Update photo...
Successfully

Update photo...
Successfully

Update photo...
Successfully

Update photo...
Successfully

Update photo...
Traceback (most recent call last):
  File "/home/user1/head/venv/lib64/python3.6/site-packages/urllib3/connection.py", line 171, in _new_conn
    (self._dns_host, self.port), self.timeout, **extra_kw)
  File "/home/user1/head/venv/lib64/python3.6/site-packages/urllib3/util/connection.py", line 56, in create_connection
    for res in socket.getaddrinfo(host, port, family, socket.SOCK_STREAM):
  File "/usr/lib64/python3.6/socket.py", line 745, in getaddrinfo
    for res in _socket.getaddrinfo(host, port, family, type, proto, flags):
socket.gaierror: [Errno -2] Name or service not known

During handling of the above exception, another exception occurred:

Traceback (most recent call last):
  File "/home/user1/head/venv/lib64/python3.6/site-packages/urllib3/connectionpool.py", line 600, in urlopen
    chunked=chunked)
  File "/home/user1/head/venv/lib64/python3.6/site-packages/urllib3/connectionpool.py", line 343, in _make_request
    self._validate_conn(conn)
  File "/home/user1/head/venv/lib64/python3.6/site-packages/urllib3/connectionpool.py", line 849, in _validate_conn
    conn.connect()
  File "/home/user1/head/venv/lib64/python3.6/site-packages/urllib3/connection.py", line 314, in connect
    conn = self._new_conn()
  File "/home/user1/head/venv/lib64/python3.6/site-packages/urllib3/connection.py", line 180, in _new_conn
    self, "Failed to establish a new connection: %s" % e)
urllib3.exceptions.NewConnectionError: <urllib3.connection.VerifiedHTTPSConnection object at 0x7f770b2d5550>: Failed to establish a new connection: [Errno -2] Name or service not known

During handling of the above exception, another exception occurred:

Traceback (most recent call last):
  File "/home/user1/head/venv/lib64/python3.6/site-packages/requests/adapters.py", line 445, in send
    timeout=timeout
  File "/home/user1/head/venv/lib64/python3.6/site-packages/urllib3/connectionpool.py", line 638, in urlopen
    _stacktrace=sys.exc_info()[2])
  File "/home/user1/head/venv/lib64/python3.6/site-packages/urllib3/util/retry.py", line 398, in increment
    raise MaxRetryError(_pool, url, error or ResponseError(cause))
urllib3.exceptions.MaxRetryError: HTTPSConnectionPool(host='api.vk.com', port=443): Max retries exceeded with url: /method/photos.getOwnerCoverPhotoUploadServer (Caused by NewConnectionError('<urllib3.connection.VerifiedHTTPSConnection object at 0x7f770b2d5550>: Failed to establish a new connection: [Errno -2] Name or service not known',))

During handling of the above exception, another exception occurred:

Traceback (most recent call last):
  File "main.py", line 93, in <module>
    main()
  File "main.py", line 89, in main
    timer( vkAPI, data, 17 )
  File "main.py", line 77, in timer
    timer( vkAPI, data, lastChecked )
  File "main.py", line 77, in timer
    timer( vkAPI, data, lastChecked )
  File "main.py", line 77, in timer
    timer( vkAPI, data, lastChecked )
  File "main.py", line 71, in timer
    upload( vkAPI, data, photo )
  File "main.py", line 50, in upload
    uploadUrl = vkAPI.photos.getOwnerCoverPhotoUploadServer( group_id = data[2], crop_x = 0, crop_y = 0, crop_x2 = 1590, crop_y2 = 400, v = '5.74' )
  File "/home/user1/head/venv/lib64/python3.6/site-packages/vk/api.py", line 173, in __call__
    return self._api._session.make_request(self)
  File "/home/user1/head/venv/lib64/python3.6/site-packages/vk/api.py", line 67, in make_request
    response = self.send_api_request(method_request, captcha_response=captcha_response)
  File "/home/user1/head/venv/lib64/python3.6/site-packages/vk/api.py", line 115, in send_api_request
    response = self.requests_session.post(url, method_args, timeout=timeout)
  File "/home/user1/head/venv/lib64/python3.6/site-packages/requests/sessions.py", line 559, in post
    return self.request('POST', url, data=data, json=json, **kwargs)
  File "/home/user1/head/venv/lib64/python3.6/site-packages/vk/utils.py", line 78, in request
    response = super(LoggingSession, self).request(method, url, **kwargs)
  File "/home/user1/head/venv/lib64/python3.6/site-packages/requests/sessions.py", line 512, in request
    resp = self.send(prep, **send_kwargs)
  File "/home/user1/head/venv/lib64/python3.6/site-packages/requests/sessions.py", line 622, in send
    r = adapter.send(request, **kwargs)
  File "/home/user1/head/venv/lib64/python3.6/site-packages/requests/adapters.py", line 513, in send
    raise ConnectionError(e, request=request)
requests.exceptions.ConnectionError: HTTPSConnectionPool(host='api.vk.com', port=443): Max retries exceeded with url: /method/photos.getOwnerCoverPhotoUploadServer (Caused by NewConnectionError('<urllib3.connection.VerifiedHTTPSConnection object at 0x7f770b2d5550>: Failed to establish a new connection: [Errno -2] Name or service not known',))
Update photo...
Successfully

Update photo...
Traceback (most recent call last):
  File "/home/user1/head/venv/lib64/python3.6/site-packages/urllib3/connection.py", line 171, in _new_conn
    (self._dns_host, self.port), self.timeout, **extra_kw)
  File "/home/user1/head/venv/lib64/python3.6/site-packages/urllib3/util/connection.py", line 56, in create_connection
    for res in socket.getaddrinfo(host, port, family, socket.SOCK_STREAM):
  File "/usr/lib64/python3.6/socket.py", line 745, in getaddrinfo
    for res in _socket.getaddrinfo(host, port, family, type, proto, flags):
socket.gaierror: [Errno -2] Name or service not known

During handling of the above exception, another exception occurred:

Traceback (most recent call last):
  File "/home/user1/head/venv/lib64/python3.6/site-packages/urllib3/connectionpool.py", line 600, in urlopen
    chunked=chunked)
  File "/home/user1/head/venv/lib64/python3.6/site-packages/urllib3/connectionpool.py", line 343, in _make_request
    self._validate_conn(conn)
  File "/home/user1/head/venv/lib64/python3.6/site-packages/urllib3/connectionpool.py", line 849, in _validate_conn
    conn.connect()
  File "/home/user1/head/venv/lib64/python3.6/site-packages/urllib3/connection.py", line 314, in connect
    conn = self._new_conn()
  File "/home/user1/head/venv/lib64/python3.6/site-packages/urllib3/connection.py", line 180, in _new_conn
    self, "Failed to establish a new connection: %s" % e)
urllib3.exceptions.NewConnectionError: <urllib3.connection.VerifiedHTTPSConnection object at 0x7fbe1bdbb550>: Failed to establish a new connection: [Errno -2] Name or service not known

During handling of the above exception, another exception occurred:

Traceback (most recent call last):
  File "/home/user1/head/venv/lib64/python3.6/site-packages/requests/adapters.py", line 445, in send
    timeout=timeout
  File "/home/user1/head/venv/lib64/python3.6/site-packages/urllib3/connectionpool.py", line 638, in urlopen
    _stacktrace=sys.exc_info()[2])
  File "/home/user1/head/venv/lib64/python3.6/site-packages/urllib3/util/retry.py", line 398, in increment
    raise MaxRetryError(_pool, url, error or ResponseError(cause))
urllib3.exceptions.MaxRetryError: HTTPSConnectionPool(host='api.vk.com', port=443): Max retries exceeded with url: /method/photos.getOwnerCoverPhotoUploadServer (Caused by NewConnectionError('<urllib3.connection.VerifiedHTTPSConnection object at 0x7fbe1bdbb550>: Failed to establish a new connection: [Errno -2] Name or service not known',))

During handling of the above exception, another exception occurred:

Traceback (most recent call last):
  File "main.py", line 93, in <module>
    main()
  File "main.py", line 89, in main
    timer( vkAPI, data, 17 )
  File "main.py", line 77, in timer
    timer( vkAPI, data, lastChecked )
  File "main.py", line 71, in timer
    upload( vkAPI, data, photo )
  File "main.py", line 50, in upload
    uploadUrl = vkAPI.photos.getOwnerCoverPhotoUploadServer( group_id = data[2], crop_x = 0, crop_y = 0, crop_x2 = 1590, crop_y2 = 400, v = '5.74' )
  File "/home/user1/head/venv/lib64/python3.6/site-packages/vk/api.py", line 173, in __call__
    return self._api._session.make_request(self)
  File "/home/user1/head/venv/lib64/python3.6/site-packages/vk/api.py", line 67, in make_request
    response = self.send_api_request(method_request, captcha_response=captcha_response)
  File "/home/user1/head/venv/lib64/python3.6/site-packages/vk/api.py", line 115, in send_api_request
    response = self.requests_session.post(url, method_args, timeout=timeout)
  File "/home/user1/head/venv/lib64/python3.6/site-packages/requests/sessions.py", line 559, in post
    return self.request('POST', url, data=data, json=json, **kwargs)
  File "/home/user1/head/venv/lib64/python3.6/site-packages/vk/utils.py", line 78, in request
    response = super(LoggingSession, self).request(method, url, **kwargs)
  File "/home/user1/head/venv/lib64/python3.6/site-packages/requests/sessions.py", line 512, in request
    resp = self.send(prep, **send_kwargs)
  File "/home/user1/head/venv/lib64/python3.6/site-packages/requests/sessions.py", line 622, in send
    r = adapter.send(request, **kwargs)
  File "/home/user1/head/venv/lib64/python3.6/site-packages/requests/adapters.py", line 513, in send
    raise ConnectionError(e, request=request)
requests.exceptions.ConnectionError: HTTPSConnectionPool(host='api.vk.com', port=443): Max retries exceeded with url: /method/photos.getOwnerCoverPhotoUploadServer (Caused by NewConnectionError('<urllib3.connection.VerifiedHTTPSConnection object at 0x7fbe1bdbb550>: Failed to establish a new connection: [Errno -2] Name or service not known',))
Update photo...
Successfully

Traceback (most recent call last):
  File "main.py", line 97, in <module>
    main()
  File "main.py", line 93, in main
    timer( vkAPI, data, 17 )
  File "main.py", line 80, in timer
    sleep( 86400 )
KeyboardInterrupt
